Workbook

Sheet Hit Trax
A1: Code | B1: Title | C1: Artist | D1: Genre
A2: LT2020 | B2: Simon Says | C2: 1910 Fruitgum Company | D2: 1960'S | E2: =LOWER(SUBSTITUTE(B2, " ", "")) -> simonsays
A3: ST6468 | B3: Aria | C3: Acker Bilk | D3: 1960'S | E3: =LOWER(SUBSTITUTE(B3, " ", "")) -> aria
A4: DT1098 | B4: How About That | C4: Adam Faith | D4: 1960'S | E4: =LOWER(SUBSTITUTE(B4, " ", "")) -> howaboutthat
A5: NOY0051 | B5: Take Good Care Of Her | C5: Adam Wade | D5: 1960'S | E5: =LOWER(SUBSTITUTE(B5, " ", "")) -> takegoodcareofher
A6: DT1141 | B6: Mary In The Morning | C6: Al Martino | D6: 1960'S | E6: =LOWER(SUBSTITUTE(B6, " ", "")) -> maryinthemorning
A7: DT1142 | B7: More Than The Eyes Can See | C7: Al Martino | D7: 1960'S | E7: =LOWER(SUBSTITUTE(B7, " ", "")) -> morethantheeyescansee
A8: DT1143 | B8: My Foolish Heart | C8: Al Martino | D8: 1960'S | E8: =LOWER(SUBSTITUTE(B8, " ", "")) -> myfoolishheart
A9: AP2670LB | B9: Spanish Eyes | C9: Al Martino | D9: 1960'S | E9: =LOWER(SUBSTITUTE(B9, " ", "")) -> spanisheyes
A10: DT1144 | B10: Spanish Eyes | C10: Al Martino | D10: 1960'S | E10: =LOWER(SUBSTITUTE(B10, " ", "")) -> spanisheyes
A11: DT1146 | B11: The Snake | C11: Al Wilson | D11: 1960'S | E11: =LOWER(SUBSTITUTE(B11, " ", "")) -> thesnake
A12: DT1148 | B12: Simon Smith And His Amazing … | C12: Alan Price | D12: 1960'S | E12: =LOWER(SUBSTITUTE(B12, " ", "")) -> simonsmithandhisamazing…
A13: ST5976 | B13: The Jarrow Song | C13: Alan Price | D13: 1960'S | E13: =LOWER(SUBSTITUTE(B13, " ", "")) -> thejarrowsong
... A15: DT1150 | B15: Hello Muddah Hello Faddah (A Letter From Camp) | C15: Alan Sherman | D15: 1960'S | E15: =LOWER(SUBSTITUTE(B15, " ", "")) -> hellomuddahhellofaddah(aletterfromcamp)
A16: 101694 | B16: Tighter Tighter | C16: Alive N Kicking | D16: 1960'S | E16: =LOWER(SUBSTITUTE(B16, " ", "")) -> tightertighter
A17: CT1453 | B17: Bell Bottom Blues | C17: Alma Cogan | D17: 1960'S | E17: =LOWER(SUBSTITUTE(B17, " ", "")) -> bellbottomblues
A18: DT7019 | B18: Bend Me Shape Me | C18: Amen Corner | D18: 1960'S | E18: =LOWER(SUBSTITUTE(B18, " ", "")) -> bendmeshapeme
A19: DT7020 | B19: If Paradise Is Half As Nice | C19: Amen Corner | D19: 1960'S | E19: =LOWER(SUBSTITUTE(B19, " ", "")) -> ifparadiseishalfasnice
A20: AP4155DS | B20: Bend Me Shape Me | C20: American Breed | D20: 1960'S | E20: =LOWER(SUBSTITUTE(B20, " ", "")) -> bendmeshapeme
A21: DT1230 | B21: Knock On Wood | C21: Ami Stewart | D21: 1960'S | E21: =LOWER(SUBSTITUTE(B21, " ", "")) -> knockonwood
A22: DT7460 | B22: Let's Live For Today (feat. Vince Gill) | C22: Amy Grant | D22: 1960'S | E22: =LOWER(SUBSTITUTE(B22, " ", "")) -> let'slivefortoday(feat.vincegill)
A23: ST5026 | B23: Almost There | C23: Andy Williams | D23: 1960'S | E23: =LOWER(SUBSTITUTE(B23, " ", "")) -> almostthere
A24: DT1254 | B24: Almost There | C24: Andy Williams | D24: 1960'S | E24: =LOWER(SUBSTITUTE(B24, " ", "")) -> almostthere
A25: DT1255 | B25: Born Free | C25: Andy Williams | D25: 1960'S | E25: =LOWER(SUBSTITUTE(B25, " ", "")) -> bornfree
A26: DT1258 | B26: Days Of Wine And Roses | C26: Andy Williams | D26: 1960'S | E26: =LOWER(SUBSTITUTE(B26, " ", "")) -> daysofwineandroses
A27: DT1260 | B27: Moon River | C27: Andy Williams | D27: 1960'S | E27: =LOWER(SUBSTITUTE(B27, " ", "")) -> moonriver
A28: DT1261 | B28: More And More | C28: Andy Williams | D28: 1960'S | E28: =LOWER(SUBSTITUTE(B28, " ", "")) -> moreandmore
... A39: DT1298 | B39: Who Can I Turn To | C39: Anthony Newley | D39: 1960'S | E39: =LOWER(SUBSTITUTE(B39, " ", "")) -> whocaniturnto
A40: 102184 | B40: Why | C40: Anthony Newley | D40: 1960'S | E40: =LOWER(SUBSTITUTE(B40, " ", "")) -> why
A41: 101647 | B41: Tighten Up | C41: Archie Bell & The Drells | D41: 1960'S | E41: =LOWER(SUBSTITUTE(B41, " ", "")) -> tightenup
A42: DT1313 | B42: Tighten Up | C42: Archie Bell And The Drells | D42: 1960'S | E42: =LOWER(SUBSTITUTE(B42, " ", "")) -> tightenup
A43: NOY0788 | B43: Coming Into Los Angeles | C43: Arlo Guthrie | D43: 1960'S | E43: =LOWER(SUBSTITUTE(B43, " ", "")) -> comingintolosangeles
A44: DT1331 | B44: I Only Have Eyes For You | C44: Art Garfunkel | D44: 1960'S | E44: =LOWER(SUBSTITUTE(B44, " ", "")) -> ionlyhaveeyesforyou
A45: LR1818 | B45: Sweet Soul Music | C45: Arthur Conley | D45: 1960'S | E45: =LOWER(SUBSTITUTE(B45, " ", "")) -> sweetsoulmusic
A46: HO0127 | B46: Nutrocker | C46: B Bumble & Stingers | D46: 1960'S | E46: =LOWER(SUBSTITUTE(B46, " ", "")) -> nutrocker
A47: AP1295H | B47: Raindrops Keep Falling On My Head | C47: B J Thomas | D47: 1960'S | E47: =LOWER(SUBSTITUTE(B47, " ", "")) -> raindropskeepfallingonmyhead
A48: DT1416 | B48: Come And Get It | C48: Badfinger | D48: 1960'S | E48: =LOWER(SUBSTITUTE(B48, " ", "")) -> comeandgetit
A49: DT1429 | B49: Yes I'm Ready | C49: Barbara Mason | D49: 1960'S | E49: =LOWER(SUBSTITUTE(B49, " ", "")) -> yesi'mready
A50: DT1437 | B50: My Man | C50: Barbra Streisand | D50: 1960'S | E50: =LOWER(SUBSTITUTE(B50, " ", "")) -> myman
A51: DT1439 | B51: People | C51: Barbra Streisand | D51: 1960'S | E51: =LOWER(SUBSTITUTE(B51, " ", "")) -> people
...

Sheet Music DB in Paper
A1: Database of weather-related popular music songs for paper submitted to Weather : Brown et al. 'Is there a Rhythm Of The Rain? An analysis of weather in popular music'
A2: Based on karafun.com, songfacts.com, bobdylan.com, www.beatlesagain.com and other sources
A3: Primary (P), Secondary (S), Not in database (ND) | B3: Song name | C3: Songwriter | D3: Performers noted in online database (www.karafun.com) | E3: Blizzard | F3: Cloud | G3: Cold / freezing / cool | H3: Fair / blue skies | I3: Fog | J3: Frost | K3: Haze | L3: Heat | M3: Hurricane | N3: Ice | O3: Mist | P3: Rain | Q3: Rainbow | R3: Seasons | S3: Snow | T3: Storm | U3: Sun | V3: Thunder / lightning | W3: Tornado | X3: Wind / breeze | Y3: Clean song name | Z3: Available on Hit Trax (Auto) | AA3: Available on Hit Trax (Manual)
A4: P | B4: 10,000 Nights Of Thunder | C4: Anders Boenloekke | D4: Alphabeat | T4: 1 | V4: 1 | Y4: =LOWER(SUBSTITUTE(CLEAN(B4), " ", "")) -> 10,000nightsofthunder | Z4: =IF(COUNTIF('Hit Trax'!E2:E23901, Y4)>0, 1, 0) -> 0 | AA4: 1
A5: P | B5: A Foggy Day (In London Town) | C5: Ira Gershwin | D5: Michael Bublé | I5: 1 | U5: 1 | Y5: =LOWER(SUBSTITUTE(CLEAN(B5), " ", "")) -> afoggyday(inlondontown) | Z5: =IF(COUNTIF('Hit Trax'!E3:E23902, Y5)>0, 1, 0) -> 0 | AA5: 1
A6: P | B6: A Marshmallow World | C6: Carl Sigman, Peter De Rose | D6: Dean Martin | F6: 1 | G6: 1 | R6: 1 | S6: 1 | U6: 1 | Y6: =LOWER(SUBSTITUTE(CLEAN(B6), " ", "")) -> amarshmallowworld | Z6: =IF(COUNTIF('Hit Trax'!E4:E23903, Y6)>0, 1, 0) -> 0 | AA6: 0
A7: P | B7: A Year Without Rain | C7: Lindy Robbins, Toby Gad | D7: Selena Gomez | P7: 1 | Y7: =LOWER(SUBSTITUTE(CLEAN(B7), " ", "")) -> ayearwithoutrain | Z7: =IF(COUNTIF('Hit Trax'!E5:E23904, Y7)>0, 1, 0) -> 0 | AA7: 0
A8: P | B8: Against The Wind | C8: Bob Seger | D8: Bob Seger | X8: 1 | Y8: =LOWER(SUBSTITUTE(CLEAN(B8), " ", "")) -> againstthewind | Z8: =IF(COUNTIF('Hit Trax'!E6:E23905, Y8)>0, 1, 0) -> 1 | AA8: 1
A9: P | B9: Ain't No Sunshine | C9: Bill Withers | D9: Bill Withers, Eva Cassidy, Michael Bolton, Kris Allen | U9: 1 | Y9: =LOWER(SUBSTITUTE(CLEAN(B9), " ", "")) -> ain'tnosunshine | Z9: =IF(COUNTIF('Hit Trax'!E7:E23906, Y9)>0, 1, 0) -> 1 | AA9: 1
A10: P | B10: April Showers | C10: Jeffrey H. Cohen, Kristian Bush, Jennifer Nettles | D10: SugarLand | P10: 1 | U10: 1 | Y10: =LOWER(SUBSTITUTE(CLEAN(B10), " ", "")) -> aprilshowers | Z10: =IF(COUNTIF('Hit Trax'!E8:E23907, Y10)>0, 1, 0) -> 1 | AA10: 1
A11: P | B11: April Sun In Cuba | C11: Marc Alexander Hunter, Paul Richard Hewson | D11: Dragon | G11: 1 | P11: 1 | R11: 1 | U11: 1 | Y11: =LOWER(SUBSTITUTE(CLEAN(B11), " ", "")) -> aprilsunincuba | Z11: =IF(COUNTIF('Hit Trax'!E9:E23908, Y11)>0, 1, 0) -> 1 | AA11: 1
A12: P | B12: Autumn | C12: Paolo Giovanni Nutini, Jim Duguid | D12: Paolo Nutini | G12: 1 | R12: 1 | Y12: =LOWER(SUBSTITUTE(CLEAN(B12), " ", "")) -> autumn | Z12: =IF(COUNTIF('Hit Trax'!E10:E23909, Y12)>0, 1, 0) -> 0 | AA12: 0
A13: P | B13: Autumn Leaves | C13: Jacques Prévert | D13: Eva Cassidy, Eric Clapton, Paula Cole, Nat King Cole, 1960s Standards | R13: 1 | Y13: =LOWER(SUBSTITUTE(CLEAN(B13), " ", "")) -> autumnleaves | Z13: =IF(COUNTIF('Hit Trax'!E11:E23910, Y13)>0, 1, 0) -> 1 | AA13: 1
A14: P | B14: Baby It's Cold Outside | C14: Frank Loesser | D14: Glee, Dean Martin, Lady Antebellum, Tom Jones | E14: 1 | G14: 1 | L14: 1 | N14: 1 | S14: 1 | T14: 1 | Y14: =LOWER(SUBSTITUTE(CLEAN(B14), " ", "")) -> babyit'scoldoutside | Z14: =IF(COUNTIF('Hit Trax'!E12:E23911, Y14)>0, 1, 0) -> 1 | AA14: 1
A15: P | B15: Before The Storm | C15: Nick Jonas, Kevin Jonas, Joseph Jonas, Miley Cyrus | D15: Jonas Brothers | P15: 1 | T15: 1 | V15: 1 | Y15: =LOWER(SUBSTITUTE(CLEAN(B15), " ", "")) -> beforethestorm | Z15: =IF(COUNTIF('Hit Trax'!E13:E23912, Y15)>0, 1, 0) -> 0 | AA15: 0
A16: P | B16: Black Hole Sun | C16: Chris Cornell | D16: Soundgarden, Paul Anka | G16: 1 | L16: 1 | P16: 1 | R16: 1 | U16: 1 | Y16: =LOWER(SUBSTITUTE(CLEAN(B16), " ", "")) -> blackholesun | Z16: =IF(COUNTIF('Hit Trax'!E14:E23913, Y16)>0, 1, 0) -> 0 | AA16: 0
A17: P | B17: Blowin' In The Wind | C17: Bob Dylan | D17: Bob Dylan, Peter, Paul and Mary | X17: 1 | Y17: =LOWER(SUBSTITUTE(CLEAN(B17), " ", "")) -> blowin'inthewind | Z17: =IF(COUNTIF('Hit Trax'!E15:E23914, Y17)>0, 1, 0) -> 0 | AA17: 0
A18: P | B18: Blowing Kisses In The Wind | C18: Peter Lord Moreland | D18: Paula Abdul | X18: 1 | Y18: =LOWER(SUBSTITUTE(CLEAN(B18), " ", "")) -> blowingkissesinthewind | Z18: =IF(COUNTIF('Hit Trax'!E16:E23915, Y18)>0, 1, 0) -> 0 | AA18: 0
A19: P | B19: Blue Skies (Berlin) | C19: Irving Berlin | D19: Willie Nelson, Eva Cassidy, Rod Stewart | H19: 1 | U19: 1 | Y19: =LOWER(SUBSTITUTE(CLEAN(B19), " ", "")) -> blueskies(berlin) | Z19: =IF(COUNTIF('Hit Trax'!E17:E23916, Y19)>0, 1, 0) -> 0 | AA19: 1
A20: P | B20: Blue Skies (Johnson and Kay) | C20: Matt Johnson, Jay Kay | D20: Jamiroquai | H20: 1 | Y20: =LOWER(SUBSTITUTE(CLEAN(B20), " ", "")) -> blueskies(johnsonandkay) | Z20: =IF(COUNTIF('Hit Trax'!E18:E23917, Y20)>0, 1, 0) -> 0 | AA20: 0
A21: P | B21: Blue Sky | C21: Dickey Betts | D21: The Allman Brothers Band | H21: 1 | U21: 1 | Y21: =LOWER(SUBSTITUTE(CLEAN(B21), " ", "")) -> bluesky | Z21: =IF(COUNTIF('Hit Trax'!E19:E23918, Y21)>0, 1, 0) -> 0 | AA21: 0
A22: P | B22: Brighter Than Sunshine | C22: Matt Hales, Ben Hales, Kimberly Oliver | D22: Aqualung | P22: 1 | U22: 1 | Y22: =LOWER(SUBSTITUTE(CLEAN(B22), " ", "")) -> brighterthansunshine | Z22: =IF(COUNTIF('Hit Trax'!E20:E23919, Y22)>0, 1, 0) -> 0 | AA22: 0
A23: P | B23: Brighter Than The Sun | C23: Ryan Tedder, Colbie Marie Caillat | D23: Colbie Caillat, Smash | U23: 1 | Y23: =LOWER(SUBSTITUTE(CLEAN(B23), " ", "")) -> brighterthanthesun | Z23: =IF(COUNTIF('Hit Trax'!E21:E23920, Y23)>0, 1, 0) -> 1 | AA23: 1
A24: P | B24: Bring Me Sunshine | C24: Sylvia Dee | D24: Morecambe and Wise, The Jive Aces | L24: 1 | U24: 1 | Y24: =LOWER(SUBSTITUTE(CLEAN(B24), " ", "")) -> bringmesunshine | Z24: =IF(COUNTIF('Hit Trax'!E22:E23921, Y24)>0, 1, 0) -> 1 | AA24: 1
A25: P | B25: Bus Stop | C25: Graham Keith Gouldman | D25: The Hollies | P25: 1 | R25: 1 | U25: 1 | X25: 1 | Y25: =LOWER(SUBSTITUTE(CLEAN(B25), " ", "")) -> busstop | Z25: =IF(COUNTIF('Hit Trax'!E23:E23922, Y25)>0, 1, 0) -> 1 | AA25: 1
A26: P | B26: Call Me The Breeze | C26: J. J. Cale | D26: Lynyrd Skynyrd | X26: 1 | Y26: =LOWER(SUBSTITUTE(CLEAN(B26), " ", "")) -> callmethebreeze | Z26: =IF(COUNTIF('Hit Trax'!E24:E23923, Y26)>0, 1, 0) -> 0 | AA26: 0
A27: P | B27: Change The World | C27: Gordon Kennedy, Wayne Kirkpatrick, Tommy Sims | D27: Eric Clapton | U27: 1 | Y27: =LOWER(SUBSTITUTE(CLEAN(B27), " ", "")) -> changetheworld | Z27: =IF(COUNTIF('Hit Trax'!E25:E23924, Y27)>0, 1, 0) -> 1 | AA27: 1
A28: P | B28: Cold As Ice | C28: Kay Denar, Rob Tyger | D28: Sarah Connor | G28: 1 | N28: 1 | S28: 1 | Y28: =LOWER(SUBSTITUTE(CLEAN(B28), " ", "")) -> coldasice | Z28: =IF(COUNTIF('Hit Trax'!E26:E23925, Y28)>0, 1, 0) -> 1 | AA28: 1
A29: P | B29: Cold Day In Hell | C29: Gary Moore | D29: Gary Moore | G29: 1 | Y29: =LOWER(SUBSTITUTE(CLEAN(B29), " ", "")) -> colddayinhell | Z29: =IF(COUNTIF('Hit Trax'!E27:E23926, Y29)>0, 1, 0) -> 0 | AA29: 0
A30: P | B30: Colder Weather | C30: Zac Brown, Wyatt Durette, Levi Lowrey, Coy Bowles | D30: Zac Brown Band | G30: 1 | R30: 1 | U30: 1 | Y30: =LOWER(SUBSTITUTE(CLEAN(B30), " ", "")) -> colderweather | Z30: =IF(COUNTIF('Hit Trax'!E28:E23927, Y30)>0, 1, 0) -> 0 | AA30: 0
A31: P | B31: Come Rain Or Come Shine | C31: Johnny Mercer | D31: Billie Holiday, Frank Sinatra | F31: 1 | P31: 1 | U31: 1 | Y31: =LOWER(SUBSTITUTE(CLEAN(B31), " ", "")) -> comerainorcomeshine | Z31: =IF(COUNTIF('Hit Trax'!E29:E23928, Y31)>0, 1, 0) -> 1 | AA31: 1
A32: P | B32: Cry Cry (Till The Sun Shines) | C32: Marv Green, Aimee Mayo, Chris Lindsey, Hillary Lee Lindsey | D32: Heidi Newfield | F32: 1 | P32: 1 | U32: 1 | Y32: =LOWER(SUBSTITUTE(CLEAN(B32), " ", "")) -> crycry(tillthesunshines) | Z32: =IF(COUNTIF('Hit Trax'!E30:E23929, Y32)>0, 1, 0) -> 0 | AA32: 0
A33: P | B33: Daddy Cool | C33: Frank Farian, George Reyam | D33: Boney M | G33: 1 | Y33: =LOWER(SUBSTITUTE(CLEAN(B33), " ", "")) -> daddycool | Z33: =IF(COUNTIF('Hit Trax'!E31:E23930, Y33)>0, 1, 0) -> 1 | AA33: 1
A34: P | B34: Don't Let The Sun Go Down On Me (Duet/Duet 45 Edit) | C34: Elton John, Bernie Taupin | D34: Elton John, Elton John, Elton John | U34: 1 | Y34: =LOWER(SUBSTITUTE(CLEAN(B34), " ", "")) -> don'tletthesungodownonme(duet/duet45edit) | Z34: =IF(COUNTIF('Hit Trax'!E32:E23931, Y34)>0, 1, 0) -> 0 | AA34: 0
A35: P | B35: Don't Rain On My Parade | C35: Bob Merrill, Jule Styne | D35: Glee, Barbra Streisand | F35: 1 | P35: 1 | U35: 1 | Y35: =LOWER(SUBSTITUTE(CLEAN(B35), " ", "")) -> don'trainonmyparade | Z35: =IF(COUNTIF('Hit Trax'!E33:E23932, Y35)>0, 1, 0) -> 1 | AA35: 1
A36: P | B36: Dust In The Wind | C36: Kerry Livgren | D36: Kansas, Scorpions | X36: 1 | Y36: =LOWER(SUBSTITUTE(CLEAN(B36), " ", "")) -> dustinthewind | Z36: =IF(COUNTIF('Hit Trax'!E34:E23933, Y36)>0, 1, 0) -> 1 | AA36: 1
A37: P | B37: Endless Summer | C37: Blair Mackichan, Andreas Litterscheidt, Marc F Jackson, Reinhard Raith, Hugo Oscar, Oceana Mahlmann, Mense Reents, Jakobus Siebels | D37: Oceana | R37: 1 | Y37: =LOWER(SUBSTITUTE(CLEAN(B37), " ", "")) -> endlesssummer | Z37: =IF(COUNTIF('Hit Trax'!E35:E23934, Y37)>0, 1, 0) -> 0 | AA37: 0
A38: P | B38: Every River | C38: Tom Littlefield, Kim Richey, Angelo Petraglia | D38: Brooks & Dunn | P38: 1 | Y38: =LOWER(SUBSTITUTE(CLEAN(B38), " ", "")) -> everyriver | Z38: =IF(COUNTIF('Hit Trax'!E36:E23935, Y38)>0, 1, 0) -> 0 | AA38: 0
A39: P | B39: Feeling Good | C39: Anthony George Newley, Leslie Bricusse | D39: Michael Bublé, Nina Simone, Muse, Michael Bublé, Adam Lambert, Michael Bublé, Ernestine Anderson | U39: 1 | X39: 1 | Y39: =LOWER(SUBSTITUTE(CLEAN(B39), " ", "")) -> feelinggood | Z39: =IF(COUNTIF('Hit Trax'!E37:E23936, Y39)>0, 1, 0) -> 1 | AA39: 1
A40: P | B40: Fire And Rain | C40: James Warren Taylor | D40: James Warren Taylor | G40: 1 | P40: 1 | U40: 1 | X40: 1 | Y40: =LOWER(SUBSTITUTE(CLEAN(B40), " ", "")) -> fireandrain | Z40: =IF(COUNTIF('Hit Trax'!E38:E23937, Y40)>0, 1, 0) -> 1 | AA40: 1
...
